Workbook

Sheet LEIA-ME
A1: Base de dados — Painel de Gestão de Leitos · Hospital Regional Horrara
A2: Dados fictícios para demonstração. Nenhum paciente, profissional ou valor é real.
A4: Data de referência (censo) | B4: 46314.292
A6: Período de análise | B6: 20/09/2026 a 19/10/2026 (30 dias). O retrato dos leitos (fLeitosCenso) é o censo de 19/10/2026 às 7h.
A7: Modelo | B7: Modelo estrela: tabelas com prefixo d são dimensões (cadastros) e com prefixo f são fatos (medições).
A8: Chave principal | B8: id_unidade (sigla da unidade) liga quase todas as tabelas; id_leito, id_procedimento, id_motivo e id_componente completam o modelo.
A9: Percentuais | B9: Gravados em fração (0,85 = 85%), com formato de porcentagem.
A10: Cores | B10: Azul: valor digitado que pode ser alterado. Fundo amarelo: data de referência usada nas fórmulas. Colunas com fórmula estão indicadas no Dicionario.
A11: Recálculo | B11: As fórmulas são recalculadas ao abrir o arquivo. Altere B4 para simular outro momento do censo.
A12: Conferência | B12: A aba Conferencia recalcula os principais indicadores a partir das tabelas e compara com os valores exibidos no painel.
A14: Aba | B14: Granularidade | C14: Linhas
A15: dUnidade | B15: unidade de internação | C15: 10
A16: dLeito | B16: leito | C16: 230
A17: dCalendario | B17: dia (últimos 30 dias) | C17: 30
A18: dProcedimento | B18: procedimento × unidade | C18: 36
A19: dMotivoDesocupacao | B19: motivo de atraso na desocupação | C19: 8
A20: dComponenteCusto | B20: componente da diária | C20: 5
A21: fCensoDiario | B21: unidade × dia | C21: 300
A22: fLeitosCenso | B22: leito no censo de 19/10/2026 às 7h | C22: 230
A23: fSaidas | B23: saída de paciente | C23: 1006
A24: fSolicitacoes | B24: pedido de leito ao NIR | C24: 831
A25: fCustoDiaria | B25: unidade × componente da diária | C25: 50
A26: fAtrasosDesocupacao | B26: episódio de atraso na desocupação | C26: 181
A27: dMetas | B27: indicador estratégico | C27: 12

Sheet dUnidade
A1: id_unidade | B1: unidade | C1: tipo_leito | D1: leitos_instalados | E1: meta_taxa_ocupacao | F1: meta_media_permanencia | G1: custo_diaria | H1: receita_media_aih
A2: CM | B2: Clínica Médica | C2: Enfermaria clínica | D2: 60 | E2: 0.85 | F2: 6.5 | G2: 1180 | H2: 1850
A3: CC | B3: Clínica Cirúrgica | C3: Enfermaria cirúrgica | D3: 40 | E3: 0.85 | F3: 4.5 | G3: 1290 | H3: 2900
A4: ORT | B4: Ortopedia/Traumatologia | C4: Enfermaria cirúrgica | D4: 24 | E4: 0.85 | F4: 5 | G4: 1240 | H4: 4300
A5: UTI | B5: UTI Adulto | C5: Terapia intensiva adulto | D5: 20 | E5: 0.9 | F5: 7 | G5: 3950 | H5: 7800
A6: UCI | B6: Semi-intensiva (UCI) | C6: Cuidados intermediários | D6: 10 | E6: 0.85 | F6: 5 | G6: 2280 | H6: 3100
A7: PED | B7: Pediatria | C7: Pediatria | D7: 20 | E7: 0.8 | F7: 4.5 | G7: 1120 | H7: 1500
A8: MAT | B8: Maternidade | C8: Obstetrícia | D8: 26 | E8: 0.8 | F8: 2.5 | G8: 980 | H8: 1100
A9: UTIN | B9: UTI Neonatal | C9: Terapia intensiva neonatal | D9: 10 | E9: 0.9 | F9: 12 | G9: 4150 | H9: 9600
A10: ONC | B10: Oncologia | C10: Oncologia | D10: 12 | E10: 0.85 | F10: 8 | G10: 1650 | H10: 2400
A11: INF | B11: Infectologia/Isolamento | C11: Isolamento | D11: 8 | E11: 0.8 | F11: 9 | G11: 1720 | H11: 3000

Sheet dLeito
A1: id_leito | B1: id_unidade | C1: ala | D1: numero
A2: CM-A01 | B2: CM | C2: A | D2: 1
A3: CM-A02 | B3: CM | C3: A | D3: 2
A4: CM-A03 | B4: CM | C4: A | D4: 3
A5: CM-A04 | B5: CM | C5: A | D5: 4
A6: CM-A05 | B6: CM | C6: A | D6: 5
A7: CM-A06 | B7: CM | C7: A | D7: 6
A8: CM-A07 | B8: CM | C8: A | D8: 7
A9: CM-A08 | B9: CM | C9: A | D9: 8
A10: CM-A09 | B10: CM | C10: A | D10: 9
A11: CM-A10 | B11: CM | C11: A | D11: 10
A12: CM-A11 | B12: CM | C12: A | D12: 11
A13: CM-A12 | B13: CM | C13: A | D13: 12
... A231: INF-B08 | B231: INF | C231: B | D231: 8

Sheet dCalendario
A1: data | B1: dia | C1: mes | D1: nome_mes | E1: ano | F1: dia_semana | G1: nome_dia | H1: fim_de_semana
A2: 46285 | B2: 20 | C2: 9 | D2: setembro | E2: 2026 | F2: 7 | G2: domingo | H2: Sim
A3: 46286 | B3: 21 | C3: 9 | D3: setembro | E3: 2026 | F3: 1 | G3: segunda-feira | H3: Não
A4: 46287 | B4: 22 | C4: 9 | D4: setembro | E4: 2026 | F4: 2 | G4: terça-feira | H4: Não
A5: 46288 | B5: 23 | C5: 9 | D5: setembro | E5: 2026 | F5: 3 | G5: quarta-feira | H5: Não
A6: 46289 | B6: 24 | C6: 9 | D6: setembro | E6: 2026 | F6: 4 | G6: quinta-feira | H6: Não
A7: 46290 | B7: 25 | C7: 9 | D7: setembro | E7: 2026 | F7: 5 | G7: sexta-feira | H7: Não
A8: 46291 | B8: 26 | C8: 9 | D8: setembro | E8: 2026 | F8: 6 | G8: sábado | H8: Sim
A9: 46292 | B9: 27 | C9: 9 | D9: setembro | E9: 2026 | F9: 7 | G9: domingo | H9: Sim
A10: 46293 | B10: 28 | C10: 9 | D10: setembro | E10: 2026 | F10: 1 | G10: segunda-feira | H10: Não
A11: 46294 | B11: 29 | C11: 9 | D11: setembro | E11: 2026 | F11: 2 | G11: terça-feira | H11: Não
A12: 46295 | B12: 30 | C12: 9 | D12: setembro | E12: 2026 | F12: 3 | G12: quarta-feira | H12: Não
A13: 46296 | B13: 1 | C13: 10 | D13: outubro | E13: 2026 | F13: 4 | G13: quinta-feira | H13: Não
... A31: 46314 | B31: 19 | C31: 10 | D31: outubro | E31: 2026 | F31: 1 | G31: segunda-feira | H31: Não

Sheet dProcedimento
A1: id_procedimento | B1: procedimento | C1: id_unidade | D1: permanencia_ref_dias
A2: PR01 | B2: Tratamento de AVC isquêmico | C2: CM | D2: 7
A3: PR02 | B3: Tratamento de DPOC exacerbada | C3: CM | D3: 5
A4: PR03 | B4: Tratamento de diabetes descompensado | C4: CM | D4: 4
A5: PR04 | B5: Tratamento de infecção do trato urinário | C5: CM | D5: 4
A6: PR05 | B6: Tratamento de insuficiência cardíaca | C6: CM | D6: 6
A7: PR06 | B7: Tratamento de pneumonias | C7: CM | D7: 5
A8: PR07 | B8: Tratamento de sepse (enfermaria) | C8: CM | D8: 8
A9: PR08 | B9: Apendicectomia | C9: CC | D9: 3
A10: PR09 | B10: Colecistectomia | C10: CC | D10: 3
A11: PR10 | B11: Gastrectomia parcial | C11: CC | D11: 7
A12: PR11 | B12: Herniorrafia inguinal | C12: CC | D12: 2
A13: PR12 | B13: Laparotomia exploradora | C13: CC | D13: 6
... A37: PR36 | B37: Tratamento de tuberculose | C37: INF | D37: 14

Sheet dMotivoDesocupacao
A1: id_motivo | B1: motivo | C1: area_responsavel | D1: acao_recomendada
A2: MD01 | B2: Alta social | C2: Serviço Social | D2: Triagem de risco social na admissão; plano de alta iniciado em até 48 h; articulação com CRAS/CREAS e família; reunião semanal de casos longos.
A3: MD02 | B3: Falta de transporte | C3: Transporte sanitário / NIR | D3: Agendar o transporte na véspera da alta prevista; escala de ambulância para altas até 10 h; sala de alta para aguardar fora do leito.
A4: MD03 | B4: Falta de acompanhante ou responsável | C4: Serviço Social | D4: Identificar o responsável na admissão; contato ativo com a família na véspera; protocolo de alta com rede de apoio.
A5: MD04 | B5: Aguardando leito de retaguarda | C5: NIR / Regulação estadual | D5: Solicitar a vaga assim que a alta for previsível; pactuar cotas com hospitais de cuidados prolongados e ILPI; escalonar casos acima de 5 dias.
A6: MD05 | B6: Aguardando atenção domiciliar | C6: Atenção domiciliar (SAD) | D6: Encaminhar ao SAD/Melhor em Casa no início da internação; checklist de oxigênio e equipamentos domiciliares.
A7: MD06 | B7: Aguardando insumo ou equipamento para alta | C7: Farmácia e suprimentos | D7: Prever órteses, curativos e oxigênio na véspera; estoque mínimo para alta; dispensação antes das 10 h.
A8: MD07 | B8: Pendência judicial ou documental | C8: Jurídico / Serviço Social | D8: Acionar Jurídico e Serviço Social no primeiro dia; modelo padronizado de comunicação ao Ministério Público e à Defensoria.
A9: MD08 | B9: Aguardando transferência para outro serviço | C9: NIR / Regulação estadual | D9: Inserir o pedido na regulação junto com a previsão de alta; acompanhamento diário pelo NIR.

Sheet dComponenteCusto
A1: id_componente | B1: componente | C1: fator_dia_de_espera
A2: CC01 | B2: Equipe assistencial (enfermagem, médica e multiprofissional) | C2: 1
A3: CC02 | B3: Hotelaria (nutrição, higienização e lavanderia) | C3: 1
A4: CC03 | B4: Medicamentos e materiais | C4: 0.35
A5: CC04 | B5: Apoio diagnóstico (laboratório e imagem) | C5: 0.15
A6: CC05 | B6: Estrutura e administração (rateio) | C6: 1

Sheet fCensoDiario
A1: data | B1: id_unidade | C1: leitos_operacionais | D1: leitos_bloqueados | E1: pacientes_dia | F1: admissoes | G1: altas | H1: obitos | I1: obitos_ate_24h | J1: transferencias_externas | K1: saidas | L1: taxa_ocupacao
A2: 46285 | B2: CM | C2: 58 | D2: 2 | E2: 53 | F2: 7 | G2: 4 | H2: 1 | I2: 0 | J2: 1 | K2: =G2+H2+J2 | L2: =IF(C2=0,0,E2/C2)
A3: 46286 | B3: CM | C3: 58 | D3: 2 | E3: 55 | F3: 5 | G3: 6 | H3: 0 | I3: 0 | J3: 0 | K3: =G3+H3+J3 | L3: =IF(C3=0,0,E3/C3)
A4: 46287 | B4: CM | C4: 59 | D4: 1 | E4: 55 | F4: 9 | G4: 6 | H4: 1 | I4: 0 | J4: 1 | K4: =G4+H4+J4 | L4: =IF(C4=0,0,E4/C4)
A5: 46288 | B5: CM | C5: 56 | D5: 4 | E5: 56 | F5: 7 | G5: 6 | H5: 0 | I5: 0 | J5: 1 | K5: =G5+H5+J5 | L5: =IF(C5=0,0,E5/C5)
A6: 46289 | B6: CM | C6: 56 | D6: 4 | E6: 56 | F6: 8 | G6: 8 | H6: 0 | I6: 0 | J6: 0 | K6: =G6+H6+J6 | L6: =IF(C6=0,0,E6/C6)
A7: 46290 | B7: CM | C7: 58 | D7: 2 | E7: 58 | F7: 10 | G7: 9 | H7: 0 | I7: 0 | J7: 0 | K7: =G7+H7+J7 | L7: =IF(C7=0,0,E7/C7)
A8: 46291 | B8: CM | C8: 58 | D8: 2 | E8: 57 | F8: 4 | G8: 4 | H8: 0 | I8: 0 | J8: 0 | K8: =G8+H8+J8 | L8: =IF(C8=0,0,E8/C8)
A9: 46292 | B9: CM | C9: 57 | D9: 3 | E9: 54 | F9: 2 | G9: 3 | H9: 1 | I9: 0 | J9: 0 | K9: =G9+H9+J9 | L9: =IF(C9=0,0,E9/C9)
A10: 46293 | B10: CM | C10: 57 | D10: 3 | E10: 56 | F10: 9 | G10: 7 | H10: 1 | I10: 0 | J10: 0 | K10: =G10+H10+J10 | L10: =IF(C10=0,0,E10/C10)
A11: 46294 | B11: CM | C11: 59 | D11: 1 | E11: 53 | F11: 10 | G11: 6 | H11: 2 | I11: 0 | J11: 0 | K11: =G11+H11+J11 | L11: =IF(C11=0,0,E11/C11)
A12: 46295 | B12: CM | C12: 57 | D12: 3 | E12: 55 | F12: 5 | G12: 8 | H12: 0 | I12: 0 | J12: 0 | K12: =G12+H12+J12 | L12: =IF(C12=0,0,E12/C12)
A13: 46296 | B13: CM | C13: 57 | D13: 3 | E13: 52 | F13: 8 | G13: 8 | H13: 0 | I13: 0 | J13: 0 | K13: =G13+H13+J13 | L13: =IF(C13=0,0,E13/C13)
... A301: 46314 | B301: INF | C301: 7 | D301: 1 | E301: 5 | F301: 0 | G301: 2 | H301: 0 | I301: 0 | J301: 0 | K301: =G301+H301+J301 | L301: =IF(C301=0,0,E301/C301)

Sheet fLeitosCenso
A1: id_leito | B1: id_unidade | C1: status | D1: etapa_fluxo | E1: prontuario | F1: iniciais | G1: idade | H1: sexo | I1: id_procedimento | J1: data_internacao | K1: dias_internacao | L1: permanencia_ref_dias | M1: razao_permanencia | N1: classificacao_kanban | O1: previsao_alta | P1: origem | Q1: pendencia | R1: motivo_bloqueio | S1: bloqueado_desde | T1: tipo_higienizacao | U1: inicio_higienizacao | V1: reservado_para | W1: reservado_desde | X1: vago_desde
A2: CM-A01 | B2: CM | C2: Ocupado | D2: Aguardando desocupação | E2: P10001 | F2: DO.S. | G2: 30 | H2: M | I2: PR07 | J2: 46311.292 | K2: =IF(C2="Ocupado",INT('LEIA-ME'!$B$4-J2),"") | L2: =IF(I2="","",INDEX(dProcedimento!$D:$D,MATCH(I2,dProcedimento!$A:$A,0))) | M2: =IF(K2="","",K2/L2) | N2: =IF(K2="","",IF(K2<=L2/2,"Verde",IF(K2<=L2,"Amarelo","Vermelho"))) | O2: 46320 | P2: Pronto-Socorro | Q2: Aguardando transferência para outro serviço
A3: CM-A02 | B3: CM | C3: Ocupado | D3: Aguardando desocupação | E3: P10002 | F3: OV.R. | G3: 56 | H3: F | I3: PR01 | J3: 46307.625 | K3: =IF(C3="Ocupado",INT('LEIA-ME'!$B$4-J3),"") | L3: =IF(I3="","",INDEX(dProcedimento!$D:$D,MATCH(I3,dProcedimento!$A:$A,0))) | M3: =IF(K3="","",K3/L3) | N3: =IF(K3="","",IF(K3<=L3/2,"Verde",IF(K3<=L3,"Amarelo","Vermelho"))) | O3: 46316 | P3: Regulação (SISREG) | Q3: Falta de acompanhante ou responsável
A4: CM-A03 | B4: CM | C4: Ocupado | D4: Em internação | E4: P10003 | F4: HE.B. | G4: 69 | H4: F | I4: PR02 | J4: 46312.167 | K4: =IF(C4="Ocupado",INT('LEIA-ME'!$B$4-J4),"") | L4: =IF(I4="","",INDEX(dProcedimento!$D:$D,MATCH(I4,dProcedimento!$A:$A,0))) | M4: =IF(K4="","",K4/L4) | N4: =IF(K4="","",IF(K4<=L4/2,"Verde",IF(K4<=L4,"Amarelo","Vermelho"))) | O4: 46319 | P4: Centro Cirúrgico
A5: CM-A04 | B5: CM | C5: Ocupado | D5: Em internação | E5: P10004 | F5: OR.E. | G5: 51 | H5: M | I5: PR04 | J5: 46312.208 | K5: =IF(C5="Ocupado",INT('LEIA-ME'!$B$4-J5),"") | L5: =IF(I5="","",INDEX(dProcedimento!$D:$D,MATCH(I5,dProcedimento!$A:$A,0))) | M5: =IF(K5="","",K5/L5) | N5: =IF(K5="","",IF(K5<=L5/2,"Verde",IF(K5<=L5,"Amarelo","Vermelho"))) | O5: 46317 | P5: Pronto-Socorro
A6: CM-A05 | B6: CM | C6: Bloqueado | D6: Bloqueado | K6: =IF(C6="Ocupado",INT('LEIA-ME'!$B$4-J6),"") | L6: =IF(I6="","",INDEX(dProcedimento!$D:$D,MATCH(I6,dProcedimento!$A:$A,0))) | M6: =IF(K6="","",K6/L6) | N6: =IF(K6="","",IF(K6<=L6/2,"Verde",IF(K6<=L6,"Amarelo","Vermelho"))) | R6: Manutenção de equipamento | S6: 46309.583
A7: CM-A06 | B7: CM | C7: Ocupado | D7: Aguardando desocupação | E7: P10005 | F7: DP.R. | G7: 39 | H7: M | I7: PR07 | J7: 46310.042 | K7: =IF(C7="Ocupado",INT('LEIA-ME'!$B$4-J7),"") | L7: =IF(I7="","",INDEX(dProcedimento!$D:$D,MATCH(I7,dProcedimento!$A:$A,0))) | M7: =IF(K7="","",K7/L7) | N7: =IF(K7="","",IF(K7<=L7/2,"Verde",IF(K7<=L7,"Amarelo","Vermelho"))) | O7: 46320 | P7: Pronto-Socorro | Q7: Aguardando leito de retaguarda
A8: CM-A07 | B8: CM | C8: Ocupado | D8: Em internação | E8: P10006 | F8: NJ.T. | G8: 58 | H8: M | I8: PR02 | J8: 46311.875 | K8: =IF(C8="Ocupado",INT('LEIA-ME'!$B$4-J8),"") | L8: =IF(I8="","",INDEX(dProcedimento!$D:$D,MATCH(I8,dProcedimento!$A:$A,0))) | M8: =IF(K8="","",K8/L8) | N8: =IF(K8="","",IF(K8<=L8/2,"Verde",IF(K8<=L8,"Amarelo","Vermelho"))) | O8: 46317 | P8: Pronto-Socorro
A9: CM-A08 | B9: CM | C9: Ocupado | D9: Em internação | E9: P10007 | F9: NO.G. | G9: 82 | H9: M | I9: PR07 | J9: 46310.958 | K9: =IF(C9="Ocupado",INT('LEIA-ME'!$B$4-J9),"") | L9: =IF(I9="","",INDEX(dProcedimento!$D:$D,MATCH(I9,dProcedimento!$A:$A,0))) | M9: =IF(K9="","",K9/L9) | N9: =IF(K9="","",IF(K9<=L9/2,"Verde",IF(K9<=L9,"Amarelo","Vermelho"))) | O9: 46318 | P9: Pronto-Socorro
A10: CM-A09 | B10: CM | C10: Ocupado | D10: Em internação | E10: P10008 | F10: IA.B. | G10: 82 | H10: F | I10: PR07 | J10: 46311.958 | K10: =IF(C10="Ocupado",INT('LEIA-ME'!$B$4-J10),"") | L10: =IF(I10="","",INDEX(dProcedimento!$D:$D,MATCH(I10,dProcedimento!$A:$A,0))) | M10: =IF(K10="","",K10/L10) | N10: =IF(K10="","",IF(K10<=L10/2,"Verde",IF(K10<=L10,"Amarelo","Vermelho"))) | O10: 46319 | P10: Transferência interna
A11: CM-A10 | B11: CM | C11: Ocupado | D11: Em internação | E11: P10009 | F11: PS.R. | G11: 71 | H11: M | I11: PR04 | J11: 46313.042 | K11: =IF(C11="Ocupado",INT('LEIA-ME'!$B$4-J11),"") | L11: =IF(I11="","",INDEX(dProcedimento!$D:$D,MATCH(I11,dProcedimento!$A:$A,0))) | M11: =IF(K11="","",K11/L11) | N11: =IF(K11="","",IF(K11<=L11/2,"Verde",IF(K11<=L11,"Amarelo","Vermelho"))) | O11: 46318 | P11: Pronto-Socorro
A12: CM-A11 | B12: CM | C12: Ocupado | D12: Aguardando desocupação | E12: P10010 | F12: IR.P. | G12: 75 | H12: M | I12: PR05 | J12: 46309.542 | K12: =IF(C12="Ocupado",INT('LEIA-ME'!$B$4-J12),"") | L12: =IF(I12="","",INDEX(dProcedimento!$D:$D,MATCH(I12,dProcedimento!$A:$A,0))) | M12: =IF(K12="","",K12/L12) | N12: =IF(K12="","",IF(K12<=L12/2,"Verde",IF(K12<=L12,"Amarelo","Vermelho"))) | O12: 46315 | P12: Pronto-Socorro | Q12: Aguardando atenção domiciliar
A13: CM-A12 | B13: CM | C13: Ocupado | D13: Alta médica dada | E13: P10011 | F13: TB.J. | G13: 70 | H13: M | I13: PR07 | J13: 46304.083 | K13: =IF(C13="Ocupado",INT('LEIA-ME'!$B$4-J13),"") | L13: =IF(I13="","",INDEX(dProcedimento!$D:$D,MATCH(I13,dProcedimento!$A:$A,0))) | M13: =IF(K13="","",K13/L13) | N13: =IF(K13="","",IF(K13<=L13/2,"Verde",IF(K13<=L13,"Amarelo","Vermelho"))) | O13: 46314 | P13: Pronto-Socorro | Q13: Aguardando procedimento cirúrgico
A14: CM-A13 | B14: CM | C14: Ocupado | D14: Aguardando desocupação | E14: P10012 | F14: PS.I. | G14: 48 | H14: M | I14: PR01 | J14: 46296.292 | K14: =IF(C14="Ocupado",INT('LEIA-ME'!$B$4-J14),"") | L14: =IF(I14="","",INDEX(dProcedimento!$D:$D,MATCH(I14,dProcedimento!$A:$A,0))) | M14: =IF(K14="","",K14/L14) | N14: =IF(K14="","",IF(K14<=L14/2,"Verde",IF(K14<=L14,"Amarelo","Vermelho"))) | O14: 46316 | P14: Regulação (SISREG) | Q14: Falta de acompanhante ou responsável
A15: CM-A14 | B15: CM | C15: Ocupado | D15: Em internação | E15: P10013 | F15: OR.C. | G15: 53 | H15: M | I15: PR05 | J15: 46307.917 | K15: =IF(C15="Ocupado",INT('LEIA-ME'!$B$4-J15),"") | L15: =IF(I15="","",INDEX(dProcedimento!$D:$D,MATCH(I15,dProcedimento!$A:$A,0))) | M15: =IF(K15="","",K15/L15) | N15: =IF(K15="","",IF(K15<=L15/2,"Verde",IF(K15<=L15,"Amarelo","Vermelho"))) | O15: 46315 | P15: Pronto-Socorro
A16: CM-A15 | B16: CM | C16: Ocupado | D16: Alta médica dada | E16: P10014 | F16: DG.O. | G16: 52 | H16: F | I16: PR01 | J16: 46306.292 | K16: =IF(C16="Ocupado",INT('LEIA-ME'!$B$4-J16),"") | L16: =IF(I16="","",INDEX(dProcedimento!$D:$D,MATCH(I16,dProcedimento!$A:$A,0))) | M16: =IF(K16="","",K16/L16) | N16: =IF(K16="","",IF(K16<=L16/2,"Verde",IF(K16<=L16,"Amarelo","Vermelho"))) | O16: 46314 | P16: Pronto-Socorro | Q16: Aguardando resultado laboratorial
A17: CM-A16 | B17: CM | C17: Ocupado | D17: Em internação | E17: P10015 | F17: AC.A. | G17: 46 | H17: M | I17: PR01 | J17: 46311.5 | K17: =IF(C17="Ocupado",INT('LEIA-ME'!$B$4-J17),"") | L17: =IF(I17="","",INDEX(dProcedimento!$D:$D,MATCH(I17,dProcedimento!$A:$A,0))) | M17: =IF(K17="","",K17/L17) | N17: =IF(K17="","",IF(K17<=L17/2,"Verde",IF(K17<=L17,"Amarelo","Vermelho"))) | O17: 46319 | P17: Pronto-Socorro
A18: CM-A17 | B18: CM | C18: Ocupado | D18: Aguardando desocupação | E18: P10016 | F18: TC.G. | G18: 41 | H18: F | I18: PR02 | J18: 46310.833 | K18: =IF(C18="Ocupado",INT('LEIA-ME'!$B$4-J18),"") | L18: =IF(I18="","",INDEX(dProcedimento!$D:$D,MATCH(I18,dProcedimento!$A:$A,0))) | M18: =IF(K18="","",K18/L18) | N18: =IF(K18="","",IF(K18<=L18/2,"Verde",IF(K18<=L18,"Amarelo","Vermelho"))) | O18: 46317 | P18: Pronto-Socorro | Q18: Aguardando leito de retaguarda
A19: CM-A18 | B19: CM | C19: Ocupado | D19: Alta prevista hoje | E19: P10017 | F19: TI.M. | G19: 51 | H19: F | I19: PR06 | J19: 46302.583 | K19: =IF(C19="Ocupado",INT('LEIA-ME'!$B$4-J19),"") | L19: =IF(I19="","",INDEX(dProcedimento!$D:$D,MATCH(I19,dProcedimento!$A:$A,0))) | M19: =IF(K19="","",K19/L19) | N19: =IF(K19="","",IF(K19<=L19/2,"Verde",IF(K19<=L19,"Amarelo","Vermelho"))) | O19: 46314 | P19: Regulação (SISREG) | Q19: Aguardando exame de imagem
A20: CM-A19 | B20: CM | C20: Ocupado | D20: Em internação | E20: P10018 | F20: LV.V. | G20: 58 | H20: M | I20: PR06 | J20: 46312.25 | K20: =IF(C20="Ocupado",INT('LEIA-ME'!$B$4-J20),"") | L20: =IF(I20="","",INDEX(dProcedimento!$D:$D,MATCH(I20,dProcedimento!$A:$A,0))) | M20: =IF(K20="","",K20/L20) | N20: =IF(K20="","",IF(K20<=L20/2,"Verde",IF(K20<=L20,"Amarelo","Vermelho"))) | O20: 46317 | P20: Pronto-Socorro
A21: CM-A20 | B21: CM | C21: Ocupado | D21: Em internação | E21: P10019 | F21: ET.H. | G21: 50 | H21: M | I21: PR04 | J21: 46312.833 | K21: =IF(C21="Ocupado",INT('LEIA-ME'!$B$4-J21),"") | L21: =IF(I21="","",INDEX(dProcedimento!$D:$D,MATCH(I21,dProcedimento!$A:$A,0))) | M21: =IF(K21="","",K21/L21) | N21: =IF(K21="","",IF(K21<=L21/2,"Verde",IF(K21<=L21,"Amarelo","Vermelho"))) | O21: 46317 | P21: Ambulatório/Eletivo
A22: CM-A21 | B22: CM | C22: Ocupado | D22: Em internação | E22: P10020 | F22: ES.J. | G22: 41 | H22: F | I22: PR02 | J22: 46310.167 | K22: =IF(C22="Ocupado",INT('LEIA-ME'!$B$4-J22),"") | L22: =IF(I22="","",INDEX(dProcedimento!$D:$D,MATCH(I22,dProcedimento!$A:$A,0))) | M22: =IF(K22="","",K22/L22) | N22: =IF(K22="","",IF(K22<=L22/2,"Verde",IF(K22<=L22,"Amarelo","Vermelho"))) | O22: 46315 | P22: Centro Cirúrgico
A23: CM-A22 | B23: CM | C23: Ocupado | D23: Em internação | E23: P10021 | F23: FE.V. | G23: 70 | H23: M | I23: PR01 | J23: 46312.25 | K23: =IF(C23="Ocupado",INT('LEIA-ME'!$B$4-J23),"") | L23: =IF(I23="","",INDEX(dProcedimento!$D:$D,MATCH(I23,dProcedimento!$A:$A,0))) | M23: =IF(K23="","",K23/L23) | N23: =IF(K23="","",IF(K23<=L23/2,"Verde",IF(K23<=L23,"Amarelo","Vermelho"))) | O23: 46320 | P23: Pronto-Socorro
A24: CM-A23 | B24: CM | C24: Em higienização | D24: Em higienização | K24: =IF(C24="Ocupado",INT('LEIA-ME'!$B$4-J24),"") | L24: =IF(I24="","",INDEX(dProcedimento!$D:$D,MATCH(I24,dProcedimento!$A:$A,0))) | M24: =IF(K24="","",K24/L24) | N24: =IF(K24="","",IF(K24<=L24/2,"Verde",IF(K24<=L24,"Amarelo","Vermelho"))) | T24: Terminal | U24: 46314.216
A25: CM-A24 | B25: CM | C25: Ocupado | D25: Em internação | E25: P10022 | F25: NE.S. | G25: 62 | H25: F | I25: PR01 | J25: 46311.833 | K25: =IF(C25="Ocupado",INT('LEIA-ME'!$B$4-J25),"") | L25: =IF(I25="","",INDEX(dProcedimento!$D:$D,MATCH(I25,dProcedimento!$A:$A,0))) | M25: =IF(K25="","",K25/L25) | N25: =IF(K25="","",IF(K25<=L25/2,"Verde",IF(K25<=L25,"Amarelo","Vermelho"))) | O25: 46320 | P25: Pronto-Socorro
A26: CM-A25 | B26: CM | C26: Ocupado | D26: Em internação | E26: P10023 | F26: AD.N. | G26: 43 | H26: F | I26: PR01 | J26: 46309.792 | K26: =IF(C26="Ocupado",INT('LEIA-ME'!$B$4-J26),"") | L26: =IF(I26="","",INDEX(dProcedimento!$D:$D,MATCH(I26,dProcedimento!$A:$A,0))) | M26: =IF(K26="","",K26/L26) | N26: =IF(K26="","",IF(K26<=L26/2,"Verde",IF(K26<=L26,"Amarelo","Vermelho"))) | O26: 46316 | P26: Centro Cirúrgico
A27: CM-A26 | B27: CM | C27: Ocupado | D27: Alta médica dada | E27: P10024 | F27: MM.A. | G27: 55 | H27: F | I27: PR06 | J27: 46308.792 | K27: =IF(C27="Ocupado",INT('LEIA-ME'!$B$4-J27),"") | L27: =IF(I27="","",INDEX(dProcedimento!$D:$D,MATCH(I27,dProcedimento!$A:$A,0))) | M27: =IF(K27="","",K27/L27) | N27: =IF(K27="","",IF(K27<=L27/2,"Verde",IF(K27<=L27,"Amarelo","Vermelho"))) | O27: 46314 | P27: Pronto-Socorro
A28: CM-A27 | B28: CM | C28: Ocupado | D28: Aguardando desocupação | E28: P10025 | F28: RL.J. | G28: 68 | H28: M | I28: PR02 | J28: 46310.042 | K28: =IF(C28="Ocupado",INT('LEIA-ME'!$B$4-J28),"") | L28: =IF(I28="","",INDEX(dProcedimento!$D:$D,MATCH(I28,dProcedimento!$A:$A,0))) | M28: =IF(K28="","",K28/L28) | N28: =IF(K28="","",IF(K28<=L28/2,"Verde",IF(K28<=L28,"Amarelo","Vermelho"))) | O28: 46316 | P28: Pronto-Socorro | Q28: Aguardando insumo ou equipamento para alta
A29: CM-A28 | B29: CM | C29: Ocupado | D29: Em internação | E29: P10026 | F29: DR.P. | G29: 51 | H29: F | I29: PR03 | J29: 46312.25 | K29: =IF(C29="Ocupado",INT('LEIA-ME'!$B$4-J29),"") | L29: =IF(I29="","",INDEX(dProcedimento!$D:$D,MATCH(I29,dProcedimento!$A:$A,0))) | M29: =IF(K29="","",K29/L29) | N29: =IF(K29="","",IF(K29<=L29/2,"Verde",IF(K29<=L29,"Amarelo","Vermelho"))) | O29: 46318 | P29: Pronto-Socorro
A30: CM-A29 | B30: CM | C30: Ocupado | D30: Em internação | E30: P10027 | F30: VS.G. | G30: 73 | H30: M | I30: PR05 | J30: 46311.583 | K30: =IF(C30="Ocupado",INT('LEIA-ME'!$B$4-J30),"") | L30: =IF(I30="","",INDEX(dProcedimento!$D:$D,MATCH(I30,dProcedimento!$A:$A,0))) | M30: =IF(K30="","",K30/L30) | N30: =IF(K30="","",IF(K30<=L30/2,"Verde",IF(K30<=L30,"Amarelo","Vermelho"))) | O30: 46317 | P30: Regulação (SISREG)
A31: CM-A30 | B31: CM | C31: Ocupado | D31: Em internação | E31: P10028 | F31: LP.H. | G31: 53 | H31: F | I31: PR02 | J31: 46309.208 | K31: =IF(C31="Ocupado",INT('LEIA-ME'!$B$4-J31),"") | L31: =IF(I31="","",INDEX(dProcedimento!$D:$D,MATCH(I31,dProcedimento!$A:$A,0))) | M31: =IF(K31="","",K31/L31) | N31: =IF(K31="","",IF(K31<=L31/2,"Verde",IF(K31<=L31,"Amarelo","Vermelho"))) | O31: 46315 | P31: Regulação (SISREG)
A32: CM-B31 | B32: CM | C32: Ocupado | D32: Alta prevista hoje | E32: P10029 | F32: BG.F. | G32: 64 | H32: F | I32: PR02 | J32: 46307.833 | K32: =IF(C32="Ocupado",INT('LEIA-ME'!$B$4-J32),"") | L32: =IF(I32="","",INDEX(dProcedimento!$D:$D,MATCH(I32,dProcedimento!$A:$A,0))) | M32: =IF(K32="","",K32/L32) | N32: =IF(K32="","",IF(K32<=L32/2,"Verde",IF(K32<=L32,"Amarelo","Vermelho"))) | O32: 46314 | P32: Regulação (SISREG) | Q32: Aguardando procedimento cirúrgico
A33: CM-B32 | B33: CM | C33: Ocupado | D33: Em internação | E33: P10030 | F33: TB.P. | G33: 74 | H33: F | I33: PR04 | J33: 46312.542 | K33: =IF(C33="Ocupado",INT('LEIA-ME'!$B$4-J33),"") | L33: =IF(I33="","",INDEX(dProcedimento!$D:$D,MATCH(I33,dProcedimento!$A:$A,0))) | M33: =IF(K33="","",K33/L33) | N33: =IF(K33="","",IF(K33<=L33/2,"Verde",IF(K33<=L33,"Amarelo","Vermelho"))) | O33: 46317 | P33: Pronto-Socorro
A34: CM-B33 | B34: CM | C34: Reservado | D34: Reservado / aguardando paciente | K34: =IF(C34="Ocupado",INT('LEIA-ME'!$B$4-J34),"") | L34: =IF(I34="","",INDEX(dProcedimento!$D:$D,MATCH(I34,dProcedimento!$A:$A,0))) | M34: =IF(K34="","",K34/L34) | N34: =IF(K34="","",IF(K34<=L34/2,"Verde",IF(K34<=L34,"Amarelo","Vermelho"))) | V34: Centro Cirúrgico | W34: 46314.199
A35: CM-B34 | B35: CM | C35: Ocupado | D35: Alta prevista hoje | E35: P10031 | F35: ES.G. | G35: 89 | H35: F | I35: PR01 | J35: 46300.292 | K35: =IF(C35="Ocupado",INT('LEIA-ME'!$B$4-J35),"") | L35: =IF(I35="","",INDEX(dProcedimento!$D:$D,MATCH(I35,dProcedimento!$A:$A,0))) | M35: =IF(K35="","",K35/L35) | N35: =IF(K35="","",IF(K35<=L35/2,"Verde",IF(K35<=L35,"Amarelo","Vermelho"))) | O35: 46314 | P35: Pronto-Socorro | Q35: Aguardando exame de imagem
A36: CM-B35 | B36: CM | C36: Bloqueado | D36: Bloqueado | K36: =IF(C36="Ocupado",INT('LEIA-ME'!$B$4-J36),"") | L36: =IF(I36="","",INDEX(dProcedimento!$D:$D,MATCH(I36,dProcedimento!$A:$A,0))) | M36: =IF(K36="","",K36/L36) | N36: =IF(K36="","",IF(K36<=L36/2,"Verde",IF(K36<=L36,"Amarelo","Vermelho"))) | R36: Manutenção de equipamento | S36: 46311.958
A37: CM-B36 | B37: CM | C37: Ocupado | D37: Em internação | E37: P10032 | F37: FN.I. | G37: 64 | H37: M | I37: PR04 | J37: 46312.667 | K37: =IF(C37="Ocupado",INT('LEIA-ME'!$B$4-J37),"") | L37: =IF(I37="","",INDEX(dProcedimento!$D:$D,MATCH(I37,dProcedimento!$A:$A,0))) | M37: =IF(K37="","",K37/L37) | N37: =IF(K37="","",IF(K37<=L37/2,"Verde",IF(K37<=L37,"Amarelo","Vermelho"))) | O37: 46316 | P37: Pronto-Socorro
A38: CM-B37 | B38: CM | C38: Bloqueado | D38: Bloqueado | K38: =IF(C38="Ocupado",INT('LEIA-ME'!$B$4-J38),"") | L38: =IF(I38="","",INDEX(dProcedimento!$D:$D,MATCH(I38,dProcedimento!$A:$A,0))) | M38: =IF(K38="","",K38/L38) | N38: =IF(K38="","",IF(K38<=L38/2,"Verde",IF(K38<=L38,"Amarelo","Vermelho"))) | R38: Desinfecção terminal | S38: 46313.583
A39: CM-B38 | B39: CM | C39: Ocupado | D39: Alta médica dada | E39: P10033 | F39: NJ.F. | G39: 69 | H39: M | I39: PR01 | J39: 46303.833 | K39: =IF(C39="Ocupado",INT('LEIA-ME'!$B$4-J39),"") | L39: =IF(I39="","",INDEX(dProcedimento!$D:$D,MATCH(I39,dProcedimento!$A:$A,0))) | M39: =IF(K39="","",K39/L39) | N39: =IF(K39="","",IF(K39<=L39/2,"Verde",IF(K39<=L39,"Amarelo","Vermelho"))) | O39: 46314 | P39: Pronto-Socorro | Q39: Aguardando parecer de especialidade
A40: CM-B39 | B40: CM | C40: Reservado | D40: Reservado / aguardando paciente | K40: =IF(C40="Ocupado",INT('LEIA-ME'!$B$4-J40),"") | L40: =IF(I40="","",INDEX(dProcedimento!$D:$D,MATCH(I40,dProcedimento!$A:$A,0))) | M40: =IF(K40="","",K40/L40) | N40: =IF(K40="","",IF(K40<=L40/2,"Verde",IF(K40<=L40,"Amarelo","Vermelho"))) | V40: Pronto-Socorro | W40: 46314.242
...

Sheet fSaidas
A1: id_saida | B1: data | C1: id_unidade | D1: tipo_saida | E1: alta_medica | F1: saida_paciente | G1: inicio_higienizacao | H1: fim_higienizacao | I1: tipo_higienizacao | J1: nova_ocupacao | K1: min_alta_ate_saida | L1: min_saida_ate_inicio_hig | M1: min_higienizacao | N1: min_liberacao_ate_ocupacao | O1: min_giro_total | P1: saida_ate_10h
A2: SA0001 | B2: 46285 | C2: CM | D2: Alta | E2: 46285.371 | F2: 46285.447 | G2: 46285.454 | H2: 46285.492 | I2: Concorrente | J2: 46285.623 | K2: 111 | L2: 10 | M2: 54 | N2: 189 | O2: 253 | P2: =IF(D2="Óbito","",IF(HOUR(F2)<10,"Sim","Não"))
A3: SA0002 | B3: 46285 | C3: CM | D3: Alta | E3: 46285.394 | F3: 46285.52 | G3: 46285.531 | H3: 46285.549 | I3: Concorrente | J3: 46285.65 | K3: 182 | L3: 16 | M3: 25 | N3: 146 | O3: 187 | P3: =IF(D3="Óbito","",IF(HOUR(F3)<10,"Sim","Não"))
A4: SA0003 | B4: 46285 | C4: CM | D4: Alta | E4: 46285.512 | F4: 46285.674 | G4: 46285.724 | H4: 46285.789 | I4: Terminal | J4: 46285.878 | K4: 233 | L4: 73 | M4: 93 | N4: 129 | O4: 295 | P4: =IF(D4="Óbito","",IF(HOUR(F4)<10,"Sim","Não"))
A5: SA0004 | B5: 46285 | C5: CM | D5: Alta | E5: 46285.545 | F5: 46285.635 | G5: 46285.659 | H5: 46285.697 | I5: Concorrente | J5: 46285.859 | K5: 130 | L5: 35 | M5: 54 | N5: 234 | O5: 322 | P5: =IF(D5="Óbito","",IF(HOUR(F5)<10,"Sim","Não"))
A6: SA0005 | B6: 46285 | C6: CM | D6: Óbito | E6: 46285.207 | F6: 46285.265 | G6: 46285.293 | H6: 46285.331 | I6: Concorrente | J6: 46285.376 | K6: 84 | L6: 41 | M6: 55 | N6: 64 | O6: 160 | P6: =IF(D6="Óbito","",IF(HOUR(F6)<10,"Sim","Não"))
A7: SA0006 | B7: 46285 | C7: CM | D7: Transferência externa | E7: 46285.424 | F7: 46285.517 | G7: 46285.551 | H7: 46285.592 | I7: Concorrente | J7: 46285.66 | K7: 133 | L7: 50 | M7: 59 | N7: 98 | O7: 206 | P7: =IF(D7="Óbito","",IF(HOUR(F7)<10,"Sim","Não"))
A8: SA0007 | B8: 46286 | C8: CM | D8: Alta | E8: 46286.424 | F8: 46286.615 | G8: 46286.622 | H8: 46286.66 | I8: Concorrente | J8: 46286.803 | K8: 275 | L8: 11 | M8: 54 | N8: 206 | O8: 272 | P8: =IF(D8="Óbito","",IF(HOUR(F8)<10,"Sim","Não"))
A9: SA0008 | B9: 46286 | C9: CM | D9: Alta | E9: 46286.515 | F9: 46286.579 | G9: 46286.588 | H9: 46286.612 | I9: Concorrente | J9: 46286.667 | K9: 92 | L9: 13 | M9: 34 | N9: 80 | O9: 128 | P9: =IF(D9="Óbito","",IF(HOUR(F9)<10,"Sim","Não"))
A10: SA0009 | B10: 46286 | C10: CM | D10: Alta | E10: 46286.393 | F10: 46286.572 | G10: 46286.59 | H10: 46286.656 | I10: Terminal | J10: 46286.794 | K10: 258 | L10: 25 | M10: 95 | N10: 199 | O10: 319 | P10: =IF(D10="Óbito","",IF(HOUR(F10)<10,"Sim","Não"))
A11: SA0010 | B11: 46286 | C11: CM | D11: Alta | E11: 46286.435 | F11: 46286.568 | G11: 46286.575 | H11: 46286.603 | I11: Concorrente | J11: 46286.619 | K11: 192 | L11: 10 | M11: 40 | N11: 24 | O11: 73 | P11: =IF(D11="Óbito","",IF(HOUR(F11)<10,"Sim","Não"))
A12: SA0011 | B12: 46286 | C12: CM | D12: Alta | E12: 46286.556 | F12: 46286.644 | G12: 46286.686 | H12: 46286.717 | I12: Concorrente | J12: 46286.789 | K12: 126 | L12: 61 | M12: 44 | N12: 103 | O12: 209 | P12: =IF(D12="Óbito","",IF(HOUR(F12)<10,"Sim","Não"))
A13: SA0012 | B13: 46286 | C13: CM | D13: Alta | E13: 46286.425 | F13: 46286.493 | G13: 46286.508 | H13: 46286.537 | I13: Concorrente | J13: 46286.581 | K13: 98 | L13: 21 | M13: 41 | N13: 63 | O13: 126 | P13: =IF(D13="Óbito","",IF(HOUR(F13)<10,"Sim","Não"))
... A1007: SA1006 | B1007: 46314 | C1007: INF | D1007: Alta | E1007: 46314.418 | F1007: 46314.552 | G1007: 46314.568 | H1007: 46314.61 | I1007: Terminal | J1007: 46314.697 | K1007: 193 | L1007: 23 | M1007: 60 | N1007: 126 | O1007: 209 | P1007: =IF(D1007="Óbito","",IF(HOUR(F1007)<10,"Sim","Não"))

Sheet fSolicitacoes
A1: id_solicitacao | B1: data_solicitacao | C1: origem | D1: id_unidade_destino | E1: prioridade | F1: data_alocacao | G1: status | H1: tempo_espera_h | I1: atendida_ate_6h
A2: SOL-00001 | B2: 46285.517 | C2: Regulação (SISREG) | D2: CM | E2: Urgência | F2: 46285.926 | G2: Atendida | H2: 9.8 | I2: =IF(AND(G2="Atendida",H2<=6),"Sim","Não")
A3: SOL-00002 | B3: 46285.57 | C3: Pronto-Socorro | D3: PED | E3: Emergência | F3: 46285.617 | G3: Atendida | H3: 1.1 | I3: =IF(AND(G3="Atendida",H3<=6),"Sim","Não")
A4: SOL-00003 | B4: 46285.103 | C4: Centro Cirúrgico | D4: UTI | E4: Eletiva | F4: 46285.597 | G4: Atendida | H4: 11.9 | I4: =IF(AND(G4="Atendida",H4<=6),"Sim","Não")
A5: SOL-00004 | B5: 46285.18 | C5: Pronto-Socorro | D5: PED | E5: Urgência | F5: 46285.306 | G5: Atendida | H5: 3 | I5: =IF(AND(G5="Atendida",H5<=6),"Sim","Não")
A6: SOL-00005 | B6: 46285.019 | C6: Ambulatório/Eletivo | D6: CM | E6: Eletiva | F6: 46285.52 | G6: Atendida | H6: 12 | I6: =IF(AND(G6="Atendida",H6<=6),"Sim","Não")
A7: SOL-00006 | B7: 46285.903 | C7: Pronto-Socorro | D7: CM | E7: Emergência | F7: 46285.995 | G7: Atendida | H7: 2.2 | I7: =IF(AND(G7="Atendida",H7<=6),"Sim","Não")
A8: SOL-00007 | B8: 46285.917 | C8: Pronto-Socorro | D8: CM | E8: Urgência | F8: 46287.601 | G8: Atendida | H8: 40.4 | I8: =IF(AND(G8="Atendida",H8<=6),"Sim","Não")
A9: SOL-00008 | B9: 46285.533 | C9: Pronto-Socorro | D9: MAT | E9: Urgência | F9: 46285.837 | G9: Atendida | H9: 7.3 | I9: =IF(AND(G9="Atendida",H9<=6),"Sim","Não")
A10: SOL-00009 | B10: 46285.7 | C10: Pronto-Socorro | D10: CM | E10: Emergência | F10: 46285.906 | G10: Atendida | H10: 4.9 | I10: =IF(AND(G10="Atendida",H10<=6),"Sim","Não")
A11: SOL-00010 | B11: 46285.903 | C11: Pronto-Socorro | D11: CM | E11: Urgência | F11: 46286.64 | G11: Atendida | H11: 17.7 | I11: =IF(AND(G11="Atendida",H11<=6),"Sim","Não")
A12: SOL-00011 | B12: 46285.298 | C12: Pronto-Socorro | D12: MAT | E12: Urgência | F12: 46285.422 | G12: Atendida | H12: 3 | I12: =IF(AND(G12="Atendida",H12<=6),"Sim","Não")
A13: SOL-00012 | B13: 46285.206 | C13: Pronto-Socorro | D13: CM | E13: Eletiva | G13: Cancelada | H13: 14.8 | I13: =IF(AND(G13="Atendida",H13<=6),"Sim","Não")
A14: SOL-00013 | B14: 46285.371 | C14: Centro Cirúrgico | D14: ORT | E14: Urgência | F14: 46286.511 | G14: Atendida | H14: 27.4 | I14: =IF(AND(G14="Atendida",H14<=6),"Sim","Não")
A15: SOL-00014 | B15: 46285.492 | C15: Pronto-Socorro | D15: UCI | E15: Urgência | F15: 46285.838 | G15: Atendida | H15: 8.3 | I15: =IF(AND(G15="Atendida",H15<=6),"Sim","Não")
A16: SOL-00015 | B16: 46285.062 | C16: Pronto-Socorro | D16: CM | E16: Emergência | F16: 46285.174 | G16: Atendida | H16: 2.7 | I16: =IF(AND(G16="Atendida",H16<=6),"Sim","Não")
A17: SOL-00016 | B17: 46285.406 | C17: Pronto-Socorro | D17: CM | E17: Eletiva | F17: 46286.607 | G17: Atendida | H17: 28.8 | I17: =IF(AND(G17="Atendida",H17<=6),"Sim","Não")
A18: SOL-00017 | B18: 46285.378 | C18: Pronto-Socorro | D18: CC | E18: Eletiva | F18: 46286.019 | G18: Atendida | H18: 15.4 | I18: =IF(AND(G18="Atendida",H18<=6),"Sim","Não")
A19: SOL-00018 | B19: 46285.998 | C19: Ambulatório/Eletivo | D19: CM | E19: Eletiva | F19: 46287.138 | G19: Atendida | H19: 27.4 | I19: =IF(AND(G19="Atendida",H19<=6),"Sim","Não")
A20: SOL-00019 | B20: 46285.826 | C20: Ambulatório/Eletivo | D20: UTI | E20: Eletiva | F20: 46289.826 | G20: Atendida | H20: 96 | I20: =IF(AND(G20="Atendida",H20<=6),"Sim","Não")
A21: SOL-00020 | B21: 46285.577 | C21: Pronto-Socorro | D21: ONC | E21: Eletiva | F21: 46286.615 | G21: Atendida | H21: 24.9 | I21: =IF(AND(G21="Atendida",H21<=6),"Sim","Não")
A22: SOL-00021 | B22: 46285 | C22: Regulação (SISREG) | D22: CM | E22: Urgência | F22: 46285.877 | G22: Atendida | H22: 21 | I22: =IF(AND(G22="Atendida",H22<=6),"Sim","Não")
A23: SOL-00022 | B23: 46285.652 | C23: Pronto-Socorro | D23: CM | E23: Emergência | F23: 46285.853 | G23: Atendida | H23: 4.8 | I23: =IF(AND(G23="Atendida",H23<=6),"Sim","Não")
A24: SOL-00023 | B24: 46285.44 | C24: Pronto-Socorro | D24: CM | E24: Eletiva | F24: 46286.088 | G24: Atendida | H24: 15.6 | I24: =IF(AND(G24="Atendida",H24<=6),"Sim","Não")
A25: SOL-00024 | B25: 46285.793 | C25: Pronto-Socorro | D25: ONC | E25: Emergência | F25: 46285.899 | G25: Atendida | H25: 2.5 | I25: =IF(AND(G25="Atendida",H25<=6),"Sim","Não")
A26: SOL-00025 | B26: 46285.663 | C26: Pronto-Socorro | D26: CC | E26: Urgência | G26: Cancelada | H26: 5.5 | I26: =IF(AND(G26="Atendida",H26<=6),"Sim","Não")
A27: SOL-00026 | B27: 46286.973 | C27: Ambulatório/Eletivo | D27: CM | E27: Eletiva | F27: 46287.251 | G27: Atendida | H27: 6.7 | I27: =IF(AND(G27="Atendida",H27<=6),"Sim","Não")
A28: SOL-00027 | B28: 46286.258 | C28: Regulação (SISREG) | D28: PED | E28: Urgência | F28: 46286.387 | G28: Atendida | H28: 3.1 | I28: =IF(AND(G28="Atendida",H28<=6),"Sim","Não")
A29: SOL-00028 | B29: 46286.469 | C29: Pronto-Socorro | D29: CM | E29: Urgência | F29: 46287.023 | G29: Atendida | H29: 13.3 | I29: =IF(AND(G29="Atendida",H29<=6),"Sim","Não")
A30: SOL-00029 | B30: 46286.513 | C30: Regulação (SISREG) | D30: MAT | E30: Urgência | F30: 46286.685 | G30: Atendida | H30: 4.1 | I30: =IF(AND(G30="Atendida",H30<=6),"Sim","Não")
A31: SOL-00030 | B31: 46286.195 | C31: Pronto-Socorro | D31: CM | E31: Eletiva | F31: 46289.614 | G31: Atendida | H31: 82.1 | I31: =IF(AND(G31="Atendida",H31<=6),"Sim","Não")
A32: SOL-00031 | B32: 46286.556 | C32: Pronto-Socorro | D32: UCI | E32: Urgência | G32: Cancelada | H32: 3.9 | I32: =IF(AND(G32="Atendida",H32<=6),"Sim","Não")
A33: SOL-00032 | B33: 46286.012 | C33: Pronto-Socorro | D33: ORT | E33: Urgência | F33: 46286.773 | G33: Atendida | H33: 18.3 | I33: =IF(AND(G33="Atendida",H33<=6),"Sim","Não")
A34: SOL-00033 | B34: 46286.912 | C34: Pronto-Socorro | D34: PED | E34: Emergência | F34: 46286.95 | G34: Atendida | H34: 0.9 | I34: =IF(AND(G34="Atendida",H34<=6),"Sim","Não")
A35: SOL-00034 | B35: 46286.723 | C35: Pronto-Socorro | D35: ORT | E35: Urgência | F35: 46287.125 | G35: Atendida | H35: 9.6 | I35: =IF(AND(G35="Atendida",H35<=6),"Sim","Não")
A36: SOL-00035 | B36: 46286.354 | C36: Pronto-Socorro | D36: UTI | E36: Urgência | F36: 46286.867 | G36: Atendida | H36: 12.3 | I36: =IF(AND(G36="Atendida",H36<=6),"Sim","Não")
A37: SOL-00036 | B37: 46286.808 | C37: Pronto-Socorro | D37: UTIN | E37: Urgência | F37: 46287.081 | G37: Atendida | H37: 6.5 | I37: =IF(AND(G37="Atendida",H37<=6),"Sim","Não")
A38: SOL-00037 | B38: 46286.606 | C38: Centro Cirúrgico | D38: CM | E38: Eletiva | F38: 46287.188 | G38: Atendida | H38: 14 | I38: =IF(AND(G38="Atendida",H38<=6),"Sim","Não")
A39: SOL-00038 | B39: 46286.53 | C39: Centro Cirúrgico | D39: CM | E39: Urgência | F39: 46286.807 | G39: Atendida | H39: 6.7 | I39: =IF(AND(G39="Atendida",H39<=6),"Sim","Não")
A40: SOL-00039 | B40: 46286.192 | C40: Pronto-Socorro | D40: UTI | E40: Eletiva | F40: 46287.017 | G40: Atendida | H40: 19.8 | I40: =IF(AND(G40="Atendida",H40<=6),"Sim","Não")
...

Sheet fCustoDiaria
A1: id_unidade | B1: id_componente | C1: valor_diaria | D1: fator_dia_de_espera | E1: valor_dia_espera
A2: CM | B2: CC01 | C2: 519.2 | D2: =INDEX(dComponenteCusto!$C:$C,MATCH(B2,dComponenteCusto!$A:$A,0)) | E2: =C2*D2
A3: CM | B3: CC02 | C3: 200.6 | D3: =INDEX(dComponenteCusto!$C:$C,MATCH(B3,dComponenteCusto!$A:$A,0)) | E3: =C3*D3
A4: CM | B4: CC03 | C4: 224.2 | D4: =INDEX(dComponenteCusto!$C:$C,MATCH(B4,dComponenteCusto!$A:$A,0)) | E4: =C4*D4
A5: CM | B5: CC04 | C5: 94.4 | D5: =INDEX(dComponenteCusto!$C:$C,MATCH(B5,dComponenteCusto!$A:$A,0)) | E5: =C5*D5
A6: CM | B6: CC05 | C6: 141.6 | D6: =INDEX(dComponenteCusto!$C:$C,MATCH(B6,dComponenteCusto!$A:$A,0)) | E6: =C6*D6
A7: CC | B7: CC01 | C7: 567.6 | D7: =INDEX(dComponenteCusto!$C:$C,MATCH(B7,dComponenteCusto!$A:$A,0)) | E7: =C7*D7
A8: CC | B8: CC02 | C8: 219.3 | D8: =INDEX(dComponenteCusto!$C:$C,MATCH(B8,dComponenteCusto!$A:$A,0)) | E8: =C8*D8
A9: CC | B9: CC03 | C9: 245.1 | D9: =INDEX(dComponenteCusto!$C:$C,MATCH(B9,dComponenteCusto!$A:$A,0)) | E9: =C9*D9
A10: CC | B10: CC04 | C10: 103.2 | D10: =INDEX(dComponenteCusto!$C:$C,MATCH(B10,dComponenteCusto!$A:$A,0)) | E10: =C10*D10
A11: CC | B11: CC05 | C11: 154.8 | D11: =INDEX(dComponenteCusto!$C:$C,MATCH(B11,dComponenteCusto!$A:$A,0)) | E11: =C11*D11
A12: ORT | B12: CC01 | C12: 545.6 | D12: =INDEX(dComponenteCusto!$C:$C,MATCH(B12,dComponenteCusto!$A:$A,0)) | E12: =C12*D12
A13: ORT | B13: CC02 | C13: 210.8 | D13: =INDEX(dComponenteCusto!$C:$C,MATCH(B13,dComponenteCusto!$A:$A,0)) | E13: =C13*D13
... A51: INF | B51: CC05 | C51: 206.4 | D51: =INDEX(dComponenteCusto!$C:$C,MATCH(B51,dComponenteCusto!$A:$A,0)) | E51: =C51*D51

Sheet fAtrasosDesocupacao
A1: id_atraso | B1: id_leito | C1: id_unidade | D1: prontuario | E1: id_motivo | F1: data_alta_medica | G1: data_desocupacao | H1: situacao | I1: dias_atraso | J1: custo_dia_espera | K1: custo_total | L1: internacoes_perdidas | M1: receita_nao_realizada
A2: DES-0100 | B2: CC-B26 | C2: CC | D2: P29265 | E2: MD02 | F2: 46285.033 | G2: 46285.363 | H2: Resolvido | I2: 0.3 | J2: =ROUND(SUMIF(fCustoDiaria!$A$2:$A$51,C2,fCustoDiaria!$E$2:$E$51),2) | K2: =ROUND(I2*J2,0) | L2: =ROUND(I2/ROUND(SUMIF(fCensoDiario!$B$2:$B$301,C2,fCensoDiario!$E$2:$E$301)/SUMIF(fCensoDiario!$B$2:$B$301,C2,fCensoDiario!$K$2:$K$301),1),2) | M2: =ROUND(I2/ROUND(SUMIF(fCensoDiario!$B$2:$B$301,C2,fCensoDiario!$E$2:$E$301)/SUMIF(fCensoDiario!$B$2:$B$301,C2,fCensoDiario!$K$2:$K$301),1)*INDEX(dUnidade!$H:$H,MATCH(C2,dUnidade!$A:$A,0)),0)
A3: DES-0082 | B3: CM-B41 | C3: CM | D3: P23647 | E3: MD02 | F3: 46285.126 | G3: 46285.578 | H3: Resolvido | I3: 0.5 | J3: =ROUND(SUMIF(fCustoDiaria!$A$2:$A$51,C3,fCustoDiaria!$E$2:$E$51),2) | K3: =ROUND(I3*J3,0) | L3: =ROUND(I3/ROUND(SUMIF(fCensoDiario!$B$2:$B$301,C3,fCensoDiario!$E$2:$E$301)/SUMIF(fCensoDiario!$B$2:$B$301,C3,fCensoDiario!$K$2:$K$301),1),2) | M3: =ROUND(I3/ROUND(SUMIF(fCensoDiario!$B$2:$B$301,C3,fCensoDiario!$E$2:$E$301)/SUMIF(fCensoDiario!$B$2:$B$301,C3,fCensoDiario!$K$2:$K$301),1)*INDEX(dUnidade!$H:$H,MATCH(C3,dUnidade!$A:$A,0)),0)
A4: DES-0181 | B4: UTI-A03 | C4: UTI | D4: P28263 | E4: MD08 | F4: 46285.272 | G4: 46286.474 | H4: Resolvido | I4: 1.2 | J4: =ROUND(SUMIF(fCustoDiaria!$A$2:$A$51,C4,fCustoDiaria!$E$2:$E$51),2) | K4: =ROUND(I4*J4,0) | L4: =ROUND(I4/ROUND(SUMIF(fCensoDiario!$B$2:$B$301,C4,fCensoDiario!$E$2:$E$301)/SUMIF(fCensoDiario!$B$2:$B$301,C4,fCensoDiario!$K$2:$K$301),1),2) | M4: =ROUND(I4/ROUND(SUMIF(fCensoDiario!$B$2:$B$301,C4,fCensoDiario!$E$2:$E$301)/SUMIF(fCensoDiario!$B$2:$B$301,C4,fCensoDiario!$K$2:$K$301),1)*INDEX(dUnidade!$H:$H,MATCH(C4,dUnidade!$A:$A,0)),0)
A5: DES-0087 | B5: CM-B59 | C5: CM | D5: P29047 | E5: MD02 | F5: 46285.568 | G5: 46287.661 | H5: Resolvido | I5: 2.1 | J5: =ROUND(SUMIF(fCustoDiaria!$A$2:$A$51,C5,fCustoDiaria!$E$2:$E$51),2) | K5: =ROUND(I5*J5,0) | L5: =ROUND(I5/ROUND(SUMIF(fCensoDiario!$B$2:$B$301,C5,fCensoDiario!$E$2:$E$301)/SUMIF(fCensoDiario!$B$2:$B$301,C5,fCensoDiario!$K$2:$K$301),1),2) | M5: =ROUND(I5/ROUND(SUMIF(fCensoDiario!$B$2:$B$301,C5,fCensoDiario!$E$2:$E$301)/SUMIF(fCensoDiario!$B$2:$B$301,C5,fCensoDiario!$K$2:$K$301),1)*INDEX(dUnidade!$H:$H,MATCH(C5,dUnidade!$A:$A,0)),0)
A6: DES-0162 | B6: UCI-B07 | C6: UCI | D6: P20930 | E6: MD03 | F6: 46285.745 | G6: 46287.057 | H6: Resolvido | I6: 1.3 | J6: =ROUND(SUMIF(fCustoDiaria!$A$2:$A$51,C6,fCustoDiaria!$E$2:$E$51),2) | K6: =ROUND(I6*J6,0) | L6: =ROUND(I6/ROUND(SUMIF(fCensoDiario!$B$2:$B$301,C6,fCensoDiario!$E$2:$E$301)/SUMIF(fCensoDiario!$B$2:$B$301,C6,fCensoDiario!$K$2:$K$301),1),2) | M6: =ROUND(I6/ROUND(SUMIF(fCensoDiario!$B$2:$B$301,C6,fCensoDiario!$E$2:$E$301)/SUMIF(fCensoDiario!$B$2:$B$301,C6,fCensoDiario!$K$2:$K$301),1)*INDEX(dUnidade!$H:$H,MATCH(C6,dUnidade!$A:$A,0)),0)
A7: DES-0138 | B7: ONC-A05 | C7: ONC | D7: P27651 | E7: MD02 | F7: 46285.792 | G7: 46286.742 | H7: Resolvido | I7: 0.9 | J7: =ROUND(SUMIF(fCustoDiaria!$A$2:$A$51,C7,fCustoDiaria!$E$2:$E$51),2) | K7: =ROUND(I7*J7,0) | L7: =ROUND(I7/ROUND(SUMIF(fCensoDiario!$B$2:$B$301,C7,fCensoDiario!$E$2:$E$301)/SUMIF(fCensoDiario!$B$2:$B$301,C7,fCensoDiario!$K$2:$K$301),1),2) | M7: =ROUND(I7/ROUND(SUMIF(fCensoDiario!$B$2:$B$301,C7,fCensoDiario!$E$2:$E$301)/SUMIF(fCensoDiario!$B$2:$B$301,C7,fCensoDiario!$K$2:$K$301),1)*INDEX(dUnidade!$H:$H,MATCH(C7,dUnidade!$A:$A,0)),0)
A8: DES-0109 | B8: CC-B23 | C8: CC | D8: P24515 | E8: MD06 | F8: 46285.867 | G8: 46287.089 | H8: Resolvido | I8: 1.2 | J8: =ROUND(SUMIF(fCustoDiaria!$A$2:$A$51,C8,fCustoDiaria!$E$2:$E$51),2) | K8: =ROUND(I8*J8,0) | L8: =ROUND(I8/ROUND(SUMIF(fCensoDiario!$B$2:$B$301,C8,fCensoDiario!$E$2:$E$301)/SUMIF(fCensoDiario!$B$2:$B$301,C8,fCensoDiario!$K$2:$K$301),1),2) | M8: =ROUND(I8/ROUND(SUMIF(fCensoDiario!$B$2:$B$301,C8,fCensoDiario!$E$2:$E$301)/SUMIF(fCensoDiario!$B$2:$B$301,C8,fCensoDiario!$K$2:$K$301),1)*INDEX(dUnidade!$H:$H,MATCH(C8,dUnidade!$A:$A,0)),0)
A9: DES-0025 | B9: CM-B53 | C9: CM | D9: P21804 | E9: MD01 | F9: 46286.074 | G9: 46287.269 | H9: Resolvido | I9: 1.2 | J9: =ROUND(SUMIF(fCustoDiaria!$A$2:$A$51,C9,fCustoDiaria!$E$2:$E$51),2) | K9: =ROUND(I9*J9,0) | L9: =ROUND(I9/ROUND(SUMIF(fCensoDiario!$B$2:$B$301,C9,fCensoDiario!$E$2:$E$301)/SUMIF(fCensoDiario!$B$2:$B$301,C9,fCensoDiario!$K$2:$K$301),1),2) | M9: =ROUND(I9/ROUND(SUMIF(fCensoDiario!$B$2:$B$301,C9,fCensoDiario!$E$2:$E$301)/SUMIF(fCensoDiario!$B$2:$B$301,C9,fCensoDiario!$K$2:$K$301),1)*INDEX(dUnidade!$H:$H,MATCH(C9,dUnidade!$A:$A,0)),0)
A10: DES-0078 | B10: CM-B57 | C10: CM | D10: P29288 | E10: MD02 | F10: 46286.226 | G10: 46286.761 | H10: Resolvido | I10: 0.5 | J10: =ROUND(SUMIF(fCustoDiaria!$A$2:$A$51,C10,fCustoDiaria!$E$2:$E$51),2) | K10: =ROUND(I10*J10,0) | L10: =ROUND(I10/ROUND(SUMIF(fCensoDiario!$B$2:$B$301,C10,fCensoDiario!$E$2:$E$301)/SUMIF(fCensoDiario!$B$2:$B$301,C10,fCensoDiario!$K$2:$K$301),1),2) | M10: =ROUND(I10/ROUND(SUMIF(fCensoDiario!$B$2:$B$301,C10,fCensoDiario!$E$2:$E$301)/SUMIF(fCensoDiario!$B$2:$B$301,C10,fCensoDiario!$K$2:$K$301),1)*INDEX(dUnidade!$H:$H,MATCH(C10,dUnidade!$A:$A,0)),0)
A11: DES-0105 | B11: CC-A16 | C11: CC | D11: P26281 | E11: MD02 | F11: 46286.245 | G11: 46288.184 | H11: Resolvido | I11: 1.9 | J11: =ROUND(SUMIF(fCustoDiaria!$A$2:$A$51,C11,fCustoDiaria!$E$2:$E$51),2) | K11: =ROUND(I11*J11,0) | L11: =ROUND(I11/ROUND(SUMIF(fCensoDiario!$B$2:$B$301,C11,fCensoDiario!$E$2:$E$301)/SUMIF(fCensoDiario!$B$2:$B$301,C11,fCensoDiario!$K$2:$K$301),1),2) | M11: =ROUND(I11/ROUND(SUMIF(fCensoDiario!$B$2:$B$301,C11,fCensoDiario!$E$2:$E$301)/SUMIF(fCensoDiario!$B$2:$B$301,C11,fCensoDiario!$K$2:$K$301),1)*INDEX(dUnidade!$H:$H,MATCH(C11,dUnidade!$A:$A,0)),0)
A12: DES-0069 | B12: CM-B38 | C12: CM | D12: P20124 | E12: MD05 | F12: 46286.524 | G12: 46289.821 | H12: Resolvido | I12: 3.3 | J12: =ROUND(SUMIF(fCustoDiaria!$A$2:$A$51,C12,fCustoDiaria!$E$2:$E$51),2) | K12: =ROUND(I12*J12,0) | L12: =ROUND(I12/ROUND(SUMIF(fCensoDiario!$B$2:$B$301,C12,fCensoDiario!$E$2:$E$301)/SUMIF(fCensoDiario!$B$2:$B$301,C12,fCensoDiario!$K$2:$K$301),1),2) | M12: =ROUND(I12/ROUND(SUMIF(fCensoDiario!$B$2:$B$301,C12,fCensoDiario!$E$2:$E$301)/SUMIF(fCensoDiario!$B$2:$B$301,C12,fCensoDiario!$K$2:$K$301),1)*INDEX(dUnidade!$H:$H,MATCH(C12,dUnidade!$A:$A,0)),0)
A13: DES-0156 | B13: INF-A01 | C13: INF | D13: P22137 | E13: MD01 | F13: 46286.644 | G13: 46287.31 | H13: Resolvido | I13: 0.7 | J13: =ROUND(SUMIF(fCustoDiaria!$A$2:$A$51,C13,fCustoDiaria!$E$2:$E$51),2) | K13: =ROUND(I13*J13,0) | L13: =ROUND(I13/ROUND(SUMIF(fCensoDiario!$B$2:$B$301,C13,fCensoDiario!$E$2:$E$301)/SUMIF(fCensoDiario!$B$2:$B$301,C13,fCensoDiario!$K$2:$K$301),1),2) | M13: =ROUND(I13/ROUND(SUMIF(fCensoDiario!$B$2:$B$301,C13,fCensoDiario!$E$2:$E$301)/SUMIF(fCensoDiario!$B$2:$B$301,C13,fCensoDiario!$K$2:$K$301),1)*INDEX(dUnidade!$H:$H,MATCH(C13,dUnidade!$A:$A,0)),0)
... A112: DES-0093 | B112: CC-B21 | C112: CC | D112: P23013 | E112: MD01 | F112: 46306.233 | G112: 46313.88 | H112: Resolvido | I112: 7.6 | J112: =ROUND(SUMIF(fCustoDiaria!$A$2:$A$51,C112,fCustoDiaria!$E$2:$E$51),2) | K112: =ROUND(I112*J112,0) | L112: =ROUND(I112/ROUND(SUMIF(fCensoDiario!$B$2:$B$301,C112,fCensoDiario!$E$2:$E$301)/SUMIF(fCensoDiario!$B$2:$B$301,C112,fCensoDiario!$K$2:$K$301),1),2) | M112: =ROUND(I112/ROUND(SUMIF(fCensoDiario!$B$2:$B$301,C112,fCensoDiario!$E$2:$E$301)/SUMIF(fCensoDiario!$B$2:$B$301,C112,fCensoDiario!$K$2:$K$301),1)*INDEX(dUnidade!$H:$H,MATCH(C112,dUnidade!$A:$A,0)),0)
A113: DES-0010 | B113: ORT-A12 | C113: ORT | D113: P10095 | E113: MD04 | F113: 46307.044 | H113: Em aberto | I113: 7.2 | J113: =ROUND(SUMIF(fCustoDiaria!$A$2:$A$51,C113,fCustoDiaria!$E$2:$E$51),2) | K113: =ROUND(I113*J113,0) | L113: =ROUND(I113/ROUND(SUMIF(fCensoDiario!$B$2:$B$301,C113,fCensoDiario!$E$2:$E$301)/SUMIF(fCensoDiario!$B$2:$B$301,C113,fCensoDiario!$K$2:$K$301),1),2) | M113: =ROUND(I113/ROUND(SUMIF(fCensoDiario!$B$2:$B$301,C113,fCensoDiario!$E$2:$E$301)/SUMIF(fCensoDiario!$B$2:$B$301,C113,fCensoDiario!$K$2:$K$301),1)*INDEX(dUnidade!$H:$H,MATCH(C113,dUnidade!$A:$A,0)),0)
A114: DES-0048 | B114: CM-A07 | C114: CM | D114: P27010 | E114: MD04 | F114: 46307.244 | G114: 46309.264 | H114: Resolvido | I114: 2 | J114: =ROUND(SUMIF(fCustoDiaria!$A$2:$A$51,C114,fCustoDiaria!$E$2:$E$51),2) | K114: =ROUND(I114*J114,0) | L114: =ROUND(I114/ROUND(SUMIF(fCensoDiario!$B$2:$B$301,C114,fCensoDiario!$E$2:$E$301)/SUMIF(fCensoDiario!$B$2:$B$301,C114,fCensoDiario!$K$2:$K$301),1),2) | M114: =ROUND(I114/ROUND(SUMIF(fCensoDiario!$B$2:$B$301,C114,fCensoDiario!$E$2:$E$301)/SUMIF(fCensoDiario!$B$2:$B$301,C114,fCensoDiario!$K$2:$K$301),1)*INDEX(dUnidade!$H:$H,MATCH(C114,dUnidade!$A:$A,0)),0)
A115: DES-0175 | B115: PED-A08 | C115: PED | D115: P27799 | E115: MD02 | F115: 46307.334 | G115: 46308.579 | H115: Resolvido | I115: 1.2 | J115: =ROUND(SUMIF(fCustoDiaria!$A$2:$A$51,C115,fCustoDiaria!$E$2:$E$51),2) | K115: =ROUND(I115*J115,0) | L115: =ROUND(I115/ROUND(SUMIF(fCensoDiario!$B$2:$B$301,C115,fCensoDiario!$E$2:$E$301)/SUMIF(fCensoDiario!$B$2:$B$301,C115,fCensoDiario!$K$2:$K$301),1),2) | M115: =ROUND(I115/ROUND(SUMIF(fCensoDiario!$B$2:$B$301,C115,fCensoDiario!$E$2:$E$301)/SUMIF(fCensoDiario!$B$2:$B$301,C115,fCensoDiario!$K$2:$K$301),1)*INDEX(dUnidade!$H:$H,MATCH(C115,dUnidade!$A:$A,0)),0)
A116: DES-0115 | B116: ORT-A07 | C116: ORT | D116: P25864 | E116: MD03 | F116: 46307.344 | G116: 46309.374 | H116: Resolvido | I116: 2 | J116: =ROUND(SUMIF(fCustoDiaria!$A$2:$A$51,C116,fCustoDiaria!$E$2:$E$51),2) | K116: =ROUND(I116*J116,0) | L116: =ROUND(I116/ROUND(SUMIF(fCensoDiario!$B$2:$B$301,C116,fCensoDiario!$E$2:$E$301)/SUMIF(fCensoDiario!$B$2:$B$301,C116,fCensoDiario!$K$2:$K$301),1),2) | M116: =ROUND(I116/ROUND(SUMIF(fCensoDiario!$B$2:$B$301,C116,fCensoDiario!$E$2:$E$301)/SUMIF(fCensoDiario!$B$2:$B$301,C116,fCensoDiario!$K$2:$K$301),1)*INDEX(dUnidade!$H:$H,MATCH(C116,dUnidade!$A:$A,0)),0)
A117: DES-0113 | B117: ORT-B19 | C117: ORT | D117: P28094 | E117: MD04 | F117: 46307.424 | G117: 46309.939 | H117: Resolvido | I117: 2.5 | J117: =ROUND(SUMIF(fCustoDiaria!$A$2:$A$51,C117,fCustoDiaria!$E$2:$E$51),2) | K117: =ROUND(I117*J117,0) | L117: =ROUND(I117/ROUND(SUMIF(fCensoDiario!$B$2:$B$301,C117,fCensoDiario!$E$2:$E$301)/SUMIF(fCensoDiario!$B$2:$B$301,C117,fCensoDiario!$K$2:$K$301),1),2) | M117: =ROUND(I117/ROUND(SUMIF(fCensoDiario!$B$2:$B$301,C117,fCensoDiario!$E$2:$E$301)/SUMIF(fCensoDiario!$B$2:$B$301,C117,fCensoDiario!$K$2:$K$301),1)*INDEX(dUnidade!$H:$H,MATCH(C117,dUnidade!$A:$A,0)),0)
A118: DES-0174 | B118: PED-A04 | C118: PED | D118: P22526 | E118: MD07 | F118: 46307.675 | G118: 46314.106 | H118: Resolvido | I118: 6.4 | J118: =ROUND(SUMIF(fCustoDiaria!$A$2:$A$51,C118,fCustoDiaria!$E$2:$E$51),2) | K118: =ROUND(I118*J118,0) | L118: =ROUND(I118/ROUND(SUMIF(fCensoDiario!$B$2:$B$301,C118,fCensoDiario!$E$2:$E$301)/SUMIF(fCensoDiario!$B$2:$B$301,C118,fCensoDiario!$K$2:$K$301),1),2) | M118: =ROUND(I118/ROUND(SUMIF(fCensoDiario!$B$2:$B$301,C118,fCensoDiario!$E$2:$E$301)/SUMIF(fCensoDiario!$B$2:$B$301,C118,fCensoDiario!$K$2:$K$301),1)*INDEX(dUnidade!$H:$H,MATCH(C118,dUnidade!$A:$A,0)),0)
A119: DES-0015 | B119: CC-B32 | C119: CC | D119: P10078 | E119: MD05 | F119: 46307.762 | H119: Em aberto | I119: 6.5 | J119: =ROUND(SUMIF(fCustoDiaria!$A$2:$A$51,C119,fCustoDiaria!$E$2:$E$51),2) | K119: =ROUND(I119*J119,0) | L119: =ROUND(I119/ROUND(SUMIF(fCensoDiario!$B$2:$B$301,C119,fCensoDiario!$E$2:$E$301)/SUMIF(fCensoDiario!$B$2:$B$301,C119,fCensoDiario!$K$2:$K$301),1),2) | M119: =ROUND(I119/ROUND(SUMIF(fCensoDiario!$B$2:$B$301,C119,fCensoDiario!$E$2:$E$301)/SUMIF(fCensoDiario!$B$2:$B$301,C119,fCensoDiario!$K$2:$K$301),1)*INDEX(dUnidade!$H:$H,MATCH(C119,dUnidade!$A:$A,0)),0)
A120: DES-0036 | B120: CM-B60 | C120: CM | D120: P25999 | E120: MD02 | F120: 46307.779 | G120: 46308.262 | H120: Resolvido | I120: 0.5 | J120: =ROUND(SUMIF(fCustoDiaria!$A$2:$A$51,C120,fCustoDiaria!$E$2:$E$51),2) | K120: =ROUND(I120*J120,0) | L120: =ROUND(I120/ROUND(SUMIF(fCensoDiario!$B$2:$B$301,C120,fCensoDiario!$E$2:$E$301)/SUMIF(fCensoDiario!$B$2:$B$301,C120,fCensoDiario!$K$2:$K$301),1),2) | M120: =ROUND(I120/ROUND(SUMIF(fCensoDiario!$B$2:$B$301,C120,fCensoDiario!$E$2:$E$301)/SUMIF(fCensoDiario!$B$2:$B$301,C120,fCensoDiario!$K$2:$K$301),1)*INDEX(dUnidade!$H:$H,MATCH(C120,dUnidade!$A:$A,0)),0)
A121: DES-0144 | B121: ONC-A05 | C121: ONC | D121: P22174 | E121: MD03 | F121: 46307.867 | G121: 46309.097 | H121: Resolvido | I121: 1.2 | J121: =ROUND(SUMIF(fCustoDiaria!$A$2:$A$51,C121,fCustoDiaria!$E$2:$E$51),2) | K121: =ROUND(I121*J121,0) | L121: =ROUND(I121/ROUND(SUMIF(fCensoDiario!$B$2:$B$301,C121,fCensoDiario!$E$2:$E$301)/SUMIF(fCensoDiario!$B$2:$B$301,C121,fCensoDiario!$K$2:$K$301),1),2) | M121: =ROUND(I121/ROUND(SUMIF(fCensoDiario!$B$2:$B$301,C121,fCensoDiario!$E$2:$E$301)/SUMIF(fCensoDiario!$B$2:$B$301,C121,fCensoDiario!$K$2:$K$301),1)*INDEX(dUnidade!$H:$H,MATCH(C121,dUnidade!$A:$A,0)),0)
A122: DES-0148 | B122: INF-A02 | C122: INF | D122: P20686 | E122: MD05 | F122: 46307.994 | G122: 46309.124 | H122: Resolvido | I122: 1.1 | J122: =ROUND(SUMIF(fCustoDiaria!$A$2:$A$51,C122,fCustoDiaria!$E$2:$E$51),2) | K122: =ROUND(I122*J122,0) | L122: =ROUND(I122/ROUND(SUMIF(fCensoDiario!$B$2:$B$301,C122,fCensoDiario!$E$2:$E$301)/SUMIF(fCensoDiario!$B$2:$B$301,C122,fCensoDiario!$K$2:$K$301),1),2) | M122: =ROUND(I122/ROUND(SUMIF(fCensoDiario!$B$2:$B$301,C122,fCensoDiario!$E$2:$E$301)/SUMIF(fCensoDiario!$B$2:$B$301,C122,fCensoDiario!$K$2:$K$301),1)*INDEX(dUnidade!$H:$H,MATCH(C122,dUnidade!$A:$A,0)),0)
A123: DES-0001 | B123: CM-A13 | C123: CM | D123: P10012 | E123: MD03 | F123: 46308.246 | H123: Em aberto | I123: 6 | J123: =ROUND(SUMIF(fCustoDiaria!$A$2:$A$51,C123,fCustoDiaria!$E$2:$E$51),2) | K123: =ROUND(I123*J123,0) | L123: =ROUND(I123/ROUND(SUMIF(fCensoDiario!$B$2:$B$301,C123,fCensoDiario!$E$2:$E$301)/SUMIF(fCensoDiario!$B$2:$B$301,C123,fCensoDiario!$K$2:$K$301),1),2) | M123: =ROUND(I123/ROUND(SUMIF(fCensoDiario!$B$2:$B$301,C123,fCensoDiario!$E$2:$E$301)/SUMIF(fCensoDiario!$B$2:$B$301,C123,fCensoDiario!$K$2:$K$301),1)*INDEX(dUnidade!$H:$H,MATCH(C123,dUnidade!$A:$A,0)),0)
A124: DES-0140 | B124: ONC-B09 | C124: ONC | D124: P26397 | E124: MD01 | F124: 46308.289 | G124: 46314.169 | H124: Resolvido | I124: 5.9 | J124: =ROUND(SUMIF(fCustoDiaria!$A$2:$A$51,C124,fCustoDiaria!$E$2:$E$51),2) | K124: =ROUND(I124*J124,0) | L124: =ROUND(I124/ROUND(SUMIF(fCensoDiario!$B$2:$B$301,C124,fCensoDiario!$E$2:$E$301)/SUMIF(fCensoDiario!$B$2:$B$301,C124,fCensoDiario!$K$2:$K$301),1),2) | M124: =ROUND(I124/ROUND(SUMIF(fCensoDiario!$B$2:$B$301,C124,fCensoDiario!$E$2:$E$301)/SUMIF(fCensoDiario!$B$2:$B$301,C124,fCensoDiario!$K$2:$K$301),1)*INDEX(dUnidade!$H:$H,MATCH(C124,dUnidade!$A:$A,0)),0)
A125: DES-0072 | B125: CM-A08 | C125: CM | D125: P28931 | E125: MD02 | F125: 46308.705 | G125: 46309.637 | H125: Resolvido | I125: 0.9 | J125: =ROUND(SUMIF(fCustoDiaria!$A$2:$A$51,C125,fCustoDiaria!$E$2:$E$51),2) | K125: =ROUND(I125*J125,0) | L125: =ROUND(I125/ROUND(SUMIF(fCensoDiario!$B$2:$B$301,C125,fCensoDiario!$E$2:$E$301)/SUMIF(fCensoDiario!$B$2:$B$301,C125,fCensoDiario!$K$2:$K$301),1),2) | M125: =ROUND(I125/ROUND(SUMIF(fCensoDiario!$B$2:$B$301,C125,fCensoDiario!$E$2:$E$301)/SUMIF(fCensoDiario!$B$2:$B$301,C125,fCensoDiario!$K$2:$K$301),1)*INDEX(dUnidade!$H:$H,MATCH(C125,dUnidade!$A:$A,0)),0)
A126: DES-0040 | B126: CM-B58 | C126: CM | D126: P27010 | E126: MD08 | F126: 46308.792 | G126: 46311.854 | H126: Resolvido | I126: 3.1 | J126: =ROUND(SUMIF(fCustoDiaria!$A$2:$A$51,C126,fCustoDiaria!$E$2:$E$51),2) | K126: =ROUND(I126*J126,0) | L126: =ROUND(I126/ROUND(SUMIF(fCensoDiario!$B$2:$B$301,C126,fCensoDiario!$E$2:$E$301)/SUMIF(fCensoDiario!$B$2:$B$301,C126,fCensoDiario!$K$2:$K$301),1),2) | M126: =ROUND(I126/ROUND(SUMIF(fCensoDiario!$B$2:$B$301,C126,fCensoDiario!$E$2:$E$301)/SUMIF(fCensoDiario!$B$2:$B$301,C126,fCensoDiario!$K$2:$K$301),1)*INDEX(dUnidade!$H:$H,MATCH(C126,dUnidade!$A:$A,0)),0)
A127: DES-0060 | B127: CM-A26 | C127: CM | D127: P21234 | E127: MD01 | F127: 46308.796 | G127: 46314.085 | H127: Resolvido | I127: 5.3 | J127: =ROUND(SUMIF(fCustoDiaria!$A$2:$A$51,C127,fCustoDiaria!$E$2:$E$51),2) | K127: =ROUND(I127*J127,0) | L127: =ROUND(I127/ROUND(SUMIF(fCensoDiario!$B$2:$B$301,C127,fCensoDiario!$E$2:$E$301)/SUMIF(fCensoDiario!$B$2:$B$301,C127,fCensoDiario!$K$2:$K$301),1),2) | M127: =ROUND(I127/ROUND(SUMIF(fCensoDiario!$B$2:$B$301,C127,fCensoDiario!$E$2:$E$301)/SUMIF(fCensoDiario!$B$2:$B$301,C127,fCensoDiario!$K$2:$K$301),1)*INDEX(dUnidade!$H:$H,MATCH(C127,dUnidade!$A:$A,0)),0)
A128: DES-0012 | B128: ORT-B14 | C128: ORT | D128: P10097 | E128: MD03 | F128: 46309.011 | H128: Em aberto | I128: 5.3 | J128: =ROUND(SUMIF(fCustoDiaria!$A$2:$A$51,C128,fCustoDiaria!$E$2:$E$51),2) | K128: =ROUND(I128*J128,0) | L128: =ROUND(I128/ROUND(SUMIF(fCensoDiario!$B$2:$B$301,C128,fCensoDiario!$E$2:$E$301)/SUMIF(fCensoDiario!$B$2:$B$301,C128,fCensoDiario!$K$2:$K$301),1),2) | M128: =ROUND(I128/ROUND(SUMIF(fCensoDiario!$B$2:$B$301,C128,fCensoDiario!$E$2:$E$301)/SUMIF(fCensoDiario!$B$2:$B$301,C128,fCensoDiario!$K$2:$K$301),1)*INDEX(dUnidade!$H:$H,MATCH(C128,dUnidade!$A:$A,0)),0)
A129: DES-0090 | B129: CC-B35 | C129: CC | D129: P20367 | E129: MD01 | F129: 46309.089 | G129: 46313.963 | H129: Resolvido | I129: 4.9 | J129: =ROUND(SUMIF(fCustoDiaria!$A$2:$A$51,C129,fCustoDiaria!$E$2:$E$51),2) | K129: =ROUND(I129*J129,0) | L129: =ROUND(I129/ROUND(SUMIF(fCensoDiario!$B$2:$B$301,C129,fCensoDiario!$E$2:$E$301)/SUMIF(fCensoDiario!$B$2:$B$301,C129,fCensoDiario!$K$2:$K$301),1),2) | M129: =ROUND(I129/ROUND(SUMIF(fCensoDiario!$B$2:$B$301,C129,fCensoDiario!$E$2:$E$301)/SUMIF(fCensoDiario!$B$2:$B$301,C129,fCensoDiario!$K$2:$K$301),1)*INDEX(dUnidade!$H:$H,MATCH(C129,dUnidade!$A:$A,0)),0)
A130: DES-0051 | B130: CM-A04 | C130: CM | D130: P23846 | E130: MD03 | F130: 46309.123 | G130: 46310.237 | H130: Resolvido | I130: 1.1 | J130: =ROUND(SUMIF(fCustoDiaria!$A$2:$A$51,C130,fCustoDiaria!$E$2:$E$51),2) | K130: =ROUND(I130*J130,0) | L130: =ROUND(I130/ROUND(SUMIF(fCensoDiario!$B$2:$B$301,C130,fCensoDiario!$E$2:$E$301)/SUMIF(fCensoDiario!$B$2:$B$301,C130,fCensoDiario!$K$2:$K$301),1),2) | M130: =ROUND(I130/ROUND(SUMIF(fCensoDiario!$B$2:$B$301,C130,fCensoDiario!$E$2:$E$301)/SUMIF(fCensoDiario!$B$2:$B$301,C130,fCensoDiario!$K$2:$K$301),1)*INDEX(dUnidade!$H:$H,MATCH(C130,dUnidade!$A:$A,0)),0)
A131: DES-0097 | B131: CC-B22 | C131: CC | D131: P22013 | E131: MD02 | F131: 46309.29 | G131: 46310.344 | H131: Resolvido | I131: 1.1 | J131: =ROUND(SUMIF(fCustoDiaria!$A$2:$A$51,C131,fCustoDiaria!$E$2:$E$51),2) | K131: =ROUND(I131*J131,0) | L131: =ROUND(I131/ROUND(SUMIF(fCensoDiario!$B$2:$B$301,C131,fCensoDiario!$E$2:$E$301)/SUMIF(fCensoDiario!$B$2:$B$301,C131,fCensoDiario!$K$2:$K$301),1),2) | M131: =ROUND(I131/ROUND(SUMIF(fCensoDiario!$B$2:$B$301,C131,fCensoDiario!$E$2:$E$301)/SUMIF(fCensoDiario!$B$2:$B$301,C131,fCensoDiario!$K$2:$K$301),1)*INDEX(dUnidade!$H:$H,MATCH(C131,dUnidade!$A:$A,0)),0)
A132: DES-0134 | B132: ONC-A01 | C132: ONC | D132: P22561 | E132: MD06 | F132: 46309.29 | G132: 46310.452 | H132: Resolvido | I132: 1.2 | J132: =ROUND(SUMIF(fCustoDiaria!$A$2:$A$51,C132,fCustoDiaria!$E$2:$E$51),2) | K132: =ROUND(I132*J132,0) | L132: =ROUND(I132/ROUND(SUMIF(fCensoDiario!$B$2:$B$301,C132,fCensoDiario!$E$2:$E$301)/SUMIF(fCensoDiario!$B$2:$B$301,C132,fCensoDiario!$K$2:$K$301),1),2) | M132: =ROUND(I132/ROUND(SUMIF(fCensoDiario!$B$2:$B$301,C132,fCensoDiario!$E$2:$E$301)/SUMIF(fCensoDiario!$B$2:$B$301,C132,fCensoDiario!$K$2:$K$301),1)*INDEX(dUnidade!$H:$H,MATCH(C132,dUnidade!$A:$A,0)),0)
A133: DES-0163 | B133: UCI-A01 | C133: UCI | D133: P28945 | E133: MD02 | F133: 46309.42 | G133: 46310.545 | H133: Resolvido | I133: 1.1 | J133: =ROUND(SUMIF(fCustoDiaria!$A$2:$A$51,C133,fCustoDiaria!$E$2:$E$51),2) | K133: =ROUND(I133*J133,0) | L133: =ROUND(I133/ROUND(SUMIF(fCensoDiario!$B$2:$B$301,C133,fCensoDiario!$E$2:$E$301)/SUMIF(fCensoDiario!$B$2:$B$301,C133,fCensoDiario!$K$2:$K$301),1),2) | M133: =ROUND(I133/ROUND(SUMIF(fCensoDiario!$B$2:$B$301,C133,fCensoDiario!$E$2:$E$301)/SUMIF(fCensoDiario!$B$2:$B$301,C133,fCensoDiario!$K$2:$K$301),1)*INDEX(dUnidade!$H:$H,MATCH(C133,dUnidade!$A:$A,0)),0)
A134: DES-0085 | B134: CM-A18 | C134: CM | D134: P28749 | E134: MD01 | F134: 46309.489 | G134: 46313.938 | H134: Resolvido | I134: 4.4 | J134: =ROUND(SUMIF(fCustoDiaria!$A$2:$A$51,C134,fCustoDiaria!$E$2:$E$51),2) | K134: =ROUND(I134*J134,0) | L134: =ROUND(I134/ROUND(SUMIF(fCensoDiario!$B$2:$B$301,C134,fCensoDiario!$E$2:$E$301)/SUMIF(fCensoDiario!$B$2:$B$301,C134,fCensoDiario!$K$2:$K$301),1),2) | M134: =ROUND(I134/ROUND(SUMIF(fCensoDiario!$B$2:$B$301,C134,fCensoDiario!$E$2:$E$301)/SUMIF(fCensoDiario!$B$2:$B$301,C134,fCensoDiario!$K$2:$K$301),1)*INDEX(dUnidade!$H:$H,MATCH(C134,dUnidade!$A:$A,0)),0)
